<!-- envs/lab_scene.xml -->
<mujoco model="xarm6_rail_cubes_bins">

  <compiler angle="radian" meshdir="assets/"/>
  <option gravity="0 0 -9.81" timestep="0.002" integrator="implicitfast"/>

  <!-- Center the viewer on the working area (bench top, slightly forward of
       the rail) and pull the camera back enough to frame the whole arm. -->
  <statistic center="0 0.15 0.95" extent="1.8"/>

  <visual>
    <headlight ambient="0.4 0.4 0.4" diffuse="0.6 0.6 0.6"/>
    <rgba haze="0.15 0.25 0.35 1"/>
    <map zfar="30"/>
    <!-- azimuth=135 looks at the scene from the front-right; elevation=-25
         tilts the view ~25 deg down so the bench/cubes/bins are clearly visible. -->
    <global azimuth="135" elevation="-25" offwidth="1280" offheight="720"/>
  </visual>

  <default>
    <default class="arm_link">
      <geom contype="2" conaffinity="1"/>
    </default>
    <default class="cube">
      <geom type="box" size="0.015 0.015 0.015" mass="0.05"
            friction="1.0 0.05 0.0001" solref="0.005 1" solimp="0.95 0.99 0.001"/>
    </default>
    <default class="bin_wall">
      <geom type="box" rgba="0.8 0.8 0.8 0.5" mass="0"
            contype="1" conaffinity="1"/>
    </default>
    <default class="tube_body">
      <geom type="cylinder" size="0.015 0.0575" mass="0.05"
            friction="1.0 0.05 0.0001" solref="0.005 1" solimp="0.95 0.99 0.001"/>
    </default>
    <default class="rack_wall">
      <geom type="box" rgba="0.85 0.85 0.85 0.7" mass="0"
            contype="1" conaffinity="1"/>
    </default>
    <default class="rack_base">
      <geom type="box" rgba="0.6 0.6 0.6 1" mass="0"
            contype="1" conaffinity="1"/>
    </default>
    <!-- 96-well SBS plate. ~127 x 85 x 14 mm. Long dimension (127 mm)
         along Y so the plate fits within the OT-2 deck's column pitch
         (132 mm cols, 89 mm rows); the short dimension (85 mm) is
         along X (row direction). Modest mass so push/pick dynamics
         feel like a real plate rather than a paperweight. -->
    <default class="well_plate_body">
      <geom type="box" size="0.0425 0.0635 0.007" mass="0.10"
            friction="1.0 0.05 0.0001"
            solref="0.005 1" solimp="0.95 0.99 0.001"/>
    </default>
    <!-- OT-2 enclosure walls: COLLIDING. The arm must enter through
         the open front face (-x, facing the bench) -- it cannot pass
         through the polycarbonate sides, back, or top. The translucent
         appearance is purely cosmetic; the physics treats these as
         hard walls. -->
    <default class="ot2_wall">
      <geom type="box" rgba="0.85 0.92 1.0 0.18" mass="0"
            contype="1" conaffinity="1"/>
    </default>
    <!-- Opentrons-style tip rack (96-position SBS tip box). Slightly
         taller than a plate (tips contribute the bulk of the height). -->
    <default class="tip_box_body">
      <geom type="box" size="0.0425 0.0635 0.040" mass="0.20"
            friction="1.0 0.05 0.0001"
            solref="0.005 1" solimp="0.95 0.99 0.001"/>
    </default>
    <!-- Heater-shaker module (152 x 90 x 82mm). Heavy-ish; meant to
         stay put on the bench. Free body so it CAN be pushed in
         principle, but the LLM should usually leave it alone. -->
    <default class="heater_shaker_body">
      <geom type="box" size="0.076 0.045 0.041" mass="2.0"
            friction="1.0 0.05 0.0001"
            solref="0.005 1" solimp="0.95 0.99 0.001"/>
    </default>
    <!-- Vortex-Genie 2 platform: high-friction top surface so objects
         placed on it follow the orbital motion via contact rather
         than welding. The platform is a child body with two slide
         joints; see <actuator> block at the bottom of the file for
         the actuators that drive its orbital motion. -->
    <default class="vortex_platform_geom">
      <geom type="cylinder" size="0.055 0.005" mass="0"
            friction="3.0 1.0 0.005"
            solref="0.005 1" solimp="0.95 0.99 0.001"/>
    </default>
  </default>

  <asset>
    <material name="red_mat"   rgba="0.9 0.2 0.2 1"/>
    <material name="green_mat" rgba="0.2 0.8 0.3 1"/>
    <material name="blue_mat"  rgba="0.2 0.4 0.9 1"/>
    <material name="red_bin_mat"   rgba="0.9 0.2 0.2 0.6"/>
    <material name="green_bin_mat" rgba="0.2 0.8 0.3 0.6"/>
    <material name="blue_bin_mat"  rgba="0.2 0.4 0.9 0.6"/>
    <!-- Falcon tube materials -->
    <material name="tube_body_mat"  rgba="0.95 0.95 0.95 0.5"/>
    <material name="cap_orange_mat" rgba="0.95 0.55 0.10 1"/>
    <material name="cap_blue_mat"   rgba="0.15 0.40 0.85 1"/>
    <!-- OT-2 instrument materials -->
    <material name="ot2_chassis_mat" rgba="0.95 0.95 0.95 1"/>
    <material name="ot2_deck_mat"    rgba="0.30 0.32 0.36 1"/>
    <material name="ot2_slot_mat"    rgba="0.55 0.55 0.60 1"/>
    <material name="ot2_frame_mat"   rgba="0.20 0.20 0.22 1"/>
    <material name="ot2_logo_mat"    rgba="0.10 0.50 0.85 1"/>
    <!-- 96-well plate material (dark blue, typical biology plate) -->
    <material name="well_plate_mat"  rgba="0.10 0.20 0.45 1"/>
    <material name="well_plate_top_mat" rgba="0.55 0.65 0.85 1"/>
    <!-- Tip box (Opentrons tip rack is typically white/grey) -->
    <material name="tip_box_mat"     rgba="0.92 0.92 0.94 1"/>
    <material name="tip_box_top_mat" rgba="0.45 0.45 0.50 1"/>
    <!-- Heater-shaker (Opentrons module is mostly dark grey with a blue accent) -->
    <material name="heater_shaker_mat"     rgba="0.20 0.22 0.26 1"/>
    <material name="heater_shaker_top_mat" rgba="0.30 0.32 0.36 1"/>
    <material name="heater_shaker_accent_mat" rgba="0.10 0.50 0.85 1"/>
    <!-- Vortex-Genie 2: classic look is grey chassis, black neck,
         dark rubber/foam top platform. -->
    <material name="vortex_chassis_mat"  rgba="0.55 0.60 0.65 1"/>
    <material name="vortex_neck_mat"     rgba="0.15 0.15 0.17 1"/>
    <material name="vortex_platform_mat" rgba="0.10 0.10 0.12 1"/>
    <material name="vortex_dial_mat"     rgba="0.85 0.85 0.88 1"/>
    <material name="vortex_logo_mat"     rgba="0.80 0.10 0.10 1"/>
    <!-- OT-2 deck slot color labels (rainbow 1-11 + dark grey TRASH).
         Each slot gets a unique-coloured corner marker so the slot
         number is visually identifiable from any angle. Slot number
         <-> colour mapping is documented in opentrons_ot2's
         safety_notes and in the LLMBrain system prompt. -->
    <material name="slot_1_mat"  rgba="0.95 0.20 0.20 1"/>   <!-- red -->
    <material name="slot_2_mat"  rgba="0.95 0.55 0.10 1"/>   <!-- orange -->
    <material name="slot_3_mat"  rgba="0.95 0.85 0.20 1"/>   <!-- yellow -->
    <material name="slot_4_mat"  rgba="0.60 0.85 0.20 1"/>   <!-- yellow-green -->
    <material name="slot_5_mat"  rgba="0.20 0.80 0.30 1"/>   <!-- green -->
    <material name="slot_6_mat"  rgba="0.20 0.80 0.70 1"/>   <!-- teal -->
    <material name="slot_7_mat"  rgba="0.20 0.65 0.95 1"/>   <!-- cyan -->
    <material name="slot_8_mat"  rgba="0.20 0.30 0.95 1"/>   <!-- blue -->
    <material name="slot_9_mat"  rgba="0.55 0.20 0.85 1"/>   <!-- purple -->
    <material name="slot_10_mat" rgba="0.95 0.45 0.75 1"/>   <!-- pink -->
    <material name="slot_11_mat" rgba="0.95 0.95 0.95 1"/>   <!-- white -->
    <material name="slot_trash_mat" rgba="0.15 0.15 0.18 1"/> <!-- dark grey -->
    <!-- LED strip materials. The base PCB is dark grey; the LED chips
         themselves have their rgba updated at runtime by
         SimXArmAPI._led_tick, so the material is just a placeholder
         (the geom_rgba overrides take precedence anyway when set). -->
    <material name="led_pcb_mat" rgba="0.12 0.12 0.13 1"/>
    <material name="led_off_mat" rgba="0.05 0.05 0.05 1"/>
    <!-- Opentrons Thermocycler Module materials. Off-white chassis with
         dark anodised heated-block + tiny blue display. -->
    <material name="pcr_chassis_mat" rgba="0.92 0.92 0.94 1"/>
    <material name="pcr_lid_mat"     rgba="0.92 0.92 0.94 1"/>
    <material name="pcr_block_mat"   rgba="0.18 0.18 0.22 1"/>
    <material name="pcr_display_mat" rgba="0.10 0.30 0.55 1"/>
    <material name="pcr_logo_mat"    rgba="0.10 0.50 0.85 1"/>
  </asset>

  <worldbody>

    <light pos="0 0 2.5" dir="0 0 -1" diffuse="0.7 0.7 0.7"/>
    <light pos="0.5 0.5 1.8" dir="-0.3 -0.3 -1" diffuse="0.4 0.4 0.4"/>

    <geom name="floor" type="plane" size="3 3 0.1"
          rgba="0.7 0.7 0.65 1" contype="1" conaffinity="1"/>

    <body name="bench" pos="0 0 0.375">
      <geom name="bench_top" type="box" size="0.75 0.45 0.375"
            rgba="0.75 0.65 0.5 1" contype="1" conaffinity="1" mass="0"/>
    </body>

    <body name="rail_track" pos="0.0 -0.05 0.75">
      <geom name="rail_geom" type="box" size="0.35 0.025 0.015"
            rgba="0.4 0.4 0.45 1" contype="0" conaffinity="0" mass="0"/>

      <body name="rail_carriage" pos="-0.35 0.0 0.02">
        <joint name="rail" type="slide" axis="1 0 0"
               range="0.0 0.7" damping="200"/>
        <geom name="carriage_geom" type="box" size="0.06 0.04 0.015"
              rgba="0.55 0.55 0.6 1" contype="1" conaffinity="1" mass="2.0"/>

        <body name="xarm_base" pos="0 0 0.02">
          <geom name="base_link" type="cylinder" size="0.06 0.04"
                rgba="0.3 0.3 0.3 1" mass="0.5" class="arm_link"/>
          <joint name="joint1" type="hinge" axis="0 0 1"
                 range="-3.14159 3.14159" damping="10"/>

          <body name="link1" pos="0 0 0.09">
            <geom name="link1_geom" type="box" size="0.055 0.055 0.11"
                  rgba="0.85 0.85 0.85 1" mass="2.16" class="arm_link"/>
            <joint name="joint2" type="hinge" axis="0 1 0"
                   range="-2.0944 2.0944" damping="10"/>

            <body name="link2" pos="0 0 0.22">
              <geom name="link2_geom" type="box" size="0.045 0.045 0.105"
                    rgba="0.85 0.85 0.85 1" mass="1.71" class="arm_link"/>
              <joint name="joint3" type="hinge" axis="0 1 0"
                     range="-3.14159 1.2217" damping="8"/>

              <body name="link3" pos="0 0 0.20">
                <geom name="link3_geom" type="box" size="0.04 0.04 0.09"
                      rgba="0.8 0.8 0.8 1" mass="1.38" class="arm_link"/>
                <joint name="joint4" type="hinge" axis="1 0 0"
                       range="-1.9199 1.9199" damping="6"/>

                <body name="link4" pos="0 0 0.175">
                  <geom name="link4_geom" type="box" size="0.035 0.035 0.075"
                        rgba="0.75 0.75 0.75 1" mass="1.05" class="arm_link"/>
                  <joint name="joint5" type="hinge" axis="0 1 0"
                         range="-2.6180 2.6180" damping="4"/>

                  <body name="link5" pos="0 0 0.13">
                    <geom name="link5_geom" type="box" size="0.03 0.03 0.055"
                          rgba="0.7 0.7 0.7 1" mass="0.72" class="arm_link"/>
                    <joint name="joint6" type="hinge" axis="1 0 0"
                           range="-1.9199 1.9199" damping="3"/>

                    <body name="link6" pos="0 0 0.075">
                      <geom name="link6_geom" type="cylinder" size="0.025 0.03"
                            rgba="0.6 0.6 0.6 1" mass="0.25" class="arm_link"/>
                      <!-- IK target marker. Kept small + translucent so it's an
                           unobtrusive cue rather than dominating the visual. -->
                      <site name="end_effector" pos="0 0 0.09"
                            size="0.005" rgba="1 0.3 0.3 0.5" type="sphere"/>
                      <body name="gripper" pos="0 0 0.06">
                        <!-- Palm: the static wrist plate. Geom name preserved
                             for FK validator (ARM_GEOM_NAMES) + weld targets. -->
                        <geom name="gripper_geom" type="box"
                              size="0.018 0.025 0.020"
                              pos="0 0 0.005"
                              rgba="0.35 0.35 0.35 1" mass="0.15"
                              class="arm_link"/>
                        <!-- Two parallel fingers extending past the EE site.
                             contype/conaffinity=0 makes them cosmetic-only (no
                             contacts), so adding them doesn't change physics
                             or invalidate existing IK trajectories. Welds
                             still do the actual grasping. Each joint qpos in
                             [0, 0.015] m: 0 = open, 0.015 = closed (inward). -->
                        <body name="finger_left" pos="0 -0.025 0.045">
                          <joint name="finger_left_joint" type="slide"
                                 axis="0 1 0" range="0 0.015" damping="2"/>
                          <geom name="finger_left_geom" type="box"
                                size="0.005 0.004 0.020"
                                rgba="0.2 0.2 0.2 1" mass="0.02"
                                contype="0" conaffinity="0"/>
                        </body>
                        <body name="finger_right" pos="0 0.025 0.045">
                          <joint name="finger_right_joint" type="slide"
                                 axis="0 -1 0" range="0 0.015" damping="2"/>
                          <geom name="finger_right_geom" type="box"
                                size="0.005 0.004 0.020"
                                rgba="0.2 0.2 0.2 1" mass="0.02"
                                contype="0" conaffinity="0"/>
                        </body>
                      </body>
                    </body>
                  </body>
                </body>
              </body>
            </body>
          </body>
        </body>

      </body>
    </body>

    <!-- Cubes -->
    <!-- (red_cube was removed; its position is now occupied by the
         Vortex-Genie 2 -- see the instruments section below.) -->
    <body name="green_cube" pos="0.00 0.15 0.78">
      <geom name="green_cube_geom" class="cube" material="green_mat"/>
      <joint type="free" name="green_cube_joint"/>
    </body>
    <body name="blue_cube" pos="0.20 0.15 0.78">
      <geom name="blue_cube_geom" class="cube" material="blue_mat"/>
      <joint type="free" name="blue_cube_joint"/>
    </body>

    <!-- Bins -->
    <!-- Bins are now FREE bodies so push_object can move them. Mass 0.5kg
         per bin -- heavy enough not to bounce around when cubes are dropped
         inside, light enough for the arm to push around.
         (red_bin was removed; its general area is now where the
         Vortex-Genie 2 sits.) -->

    <body name="green_bin" pos="0.00 0.35 0.75">
      <inertial pos="0 0 0.020" mass="0.5" diaginertia="6e-4 6e-4 9e-4"/>
      <joint type="free" name="green_bin_joint"/>
      <geom name="green_bin_floor" type="box" size="0.040 0.040 0.001"
            pos="0 0 0.001" material="green_bin_mat"
            contype="1" conaffinity="1" mass="0"/>
      <geom name="green_bin_w_front" class="bin_wall"
            size="0.040 0.002 0.030" pos="0 -0.040 0.030"/>
      <geom name="green_bin_w_back"  class="bin_wall"
            size="0.040 0.002 0.030" pos="0  0.040 0.030"/>
      <geom name="green_bin_w_left"  class="bin_wall"
            size="0.002 0.040 0.030" pos="-0.040 0 0.030"/>
      <geom name="green_bin_w_right" class="bin_wall"
            size="0.002 0.040 0.030" pos=" 0.040 0 0.030"/>
    </body>

    <body name="blue_bin" pos="0.20 0.35 0.75">
      <inertial pos="0 0 0.020" mass="0.5" diaginertia="6e-4 6e-4 9e-4"/>
      <joint type="free" name="blue_bin_joint"/>
      <geom name="blue_bin_floor" type="box" size="0.040 0.040 0.001"
            pos="0 0 0.001" material="blue_bin_mat"
            contype="1" conaffinity="1" mass="0"/>
      <geom name="blue_bin_w_front" class="bin_wall"
            size="0.040 0.002 0.030" pos="0 -0.040 0.030"/>
      <geom name="blue_bin_w_back"  class="bin_wall"
            size="0.040 0.002 0.030" pos="0  0.040 0.030"/>
      <geom name="blue_bin_w_left"  class="bin_wall"
            size="0.002 0.040 0.030" pos="-0.040 0 0.030"/>
      <geom name="blue_bin_w_right" class="bin_wall"
            size="0.002 0.040 0.030" pos=" 0.040 0 0.030"/>
    </body>

    <!-- ============================================================
         FALCON TUBE RACKS (2 racks x 8 slots each in a 4-col x 2-row grid)
         Currently populated with 3 tubes per rack, scattered across the grid
         so empty slots are visible.

         Grid layout (rack-local coords; rack centered at its body origin):
           Columns at x = -0.060, -0.020, +0.020, +0.060  (40mm pitch)
           Rows    at y = -0.020, +0.020                 (40mm pitch)
           => slot internal size 32 x 32 mm (room for 30 mm OD tubes)

         Construction: shared walls. Outer perimeter (4) + internal vertical
         separators between columns (3) + internal horizontal separator between
         rows (1) = 8 wall geoms per rack. Walls are 50mm tall.

         Tube specs: 30mm OD x 115mm body, 31mm cap x 12mm, body center at
         rack-frame z = 0.0625 (tube bottom rests on base plate top).
    ============================================================ -->

    <!-- LEFT RACK at x=-0.45, y=0.15. Holds L1, L2, L3 scattered across slots.
         Free body so it can be pushed (mass ~250g). -->
    <body name="left_tube_rack" pos="-0.45 0.15 0.755">
      <inertial pos="0 0 0.020" mass="0.25" diaginertia="3e-4 7e-4 8e-4"/>
      <joint type="free" name="left_tube_rack_joint"/>
      <geom name="left_rack_base" class="rack_base" size="0.085 0.045 0.005"
            pos="0 0 0"/>
      <!-- Outer perimeter -->
      <geom name="L_outer_front" class="rack_wall" size="0.080 0.001 0.025" pos=" 0.000 -0.040 0.030"/>
      <geom name="L_outer_back"  class="rack_wall" size="0.080 0.001 0.025" pos=" 0.000  0.040 0.030"/>
      <geom name="L_outer_left"  class="rack_wall" size="0.001 0.040 0.025" pos="-0.080  0.000 0.030"/>
      <geom name="L_outer_right" class="rack_wall" size="0.001 0.040 0.025" pos=" 0.080  0.000 0.030"/>
      <!-- Internal vertical separators (3, between the 4 columns) -->
      <geom name="L_sep_v1" class="rack_wall" size="0.001 0.040 0.025" pos="-0.040 0 0.030"/>
      <geom name="L_sep_v2" class="rack_wall" size="0.001 0.040 0.025" pos=" 0.000 0 0.030"/>
      <geom name="L_sep_v3" class="rack_wall" size="0.001 0.040 0.025" pos=" 0.040 0 0.030"/>
      <!-- Internal horizontal separator (1, between the 2 rows) -->
      <geom name="L_sep_h1" class="rack_wall" size="0.080 0.001 0.025" pos="0 0 0.030"/>
    </body>

    <!-- RIGHT RACK at x=+0.45, y=0.15. Holds R1, R2, R3.
         Free body (same as left). -->
    <!-- right_tube_rack: despite the name, this rack has been MOVED to
         the back-left of the bench (directly behind left_tube_rack).
         The "right" in the name is historical -- pre-existing
         lessons.md and world_model.md entries reference it, so we keep
         the identifier to avoid invalidating that history. -->
    <body name="right_tube_rack" pos="-0.45 0.30 0.755">
      <inertial pos="0 0 0.020" mass="0.25" diaginertia="3e-4 7e-4 8e-4"/>
      <joint type="free" name="right_tube_rack_joint"/>
      <geom name="right_rack_base" class="rack_base" size="0.085 0.045 0.005"
            pos="0 0 0"/>
      <geom name="R_outer_front" class="rack_wall" size="0.080 0.001 0.025" pos=" 0.000 -0.040 0.030"/>
      <geom name="R_outer_back"  class="rack_wall" size="0.080 0.001 0.025" pos=" 0.000  0.040 0.030"/>
      <geom name="R_outer_left"  class="rack_wall" size="0.001 0.040 0.025" pos="-0.080  0.000 0.030"/>
      <geom name="R_outer_right" class="rack_wall" size="0.001 0.040 0.025" pos=" 0.080  0.000 0.030"/>
      <geom name="R_sep_v1" class="rack_wall" size="0.001 0.040 0.025" pos="-0.040 0 0.030"/>
      <geom name="R_sep_v2" class="rack_wall" size="0.001 0.040 0.025" pos=" 0.000 0 0.030"/>
      <geom name="R_sep_v3" class="rack_wall" size="0.001 0.040 0.025" pos=" 0.040 0 0.030"/>
      <geom name="R_sep_h1" class="rack_wall" size="0.080 0.001 0.025" pos="0 0 0.030"/>
    </body>

    <!-- TUBES — free bodies. 3 per rack, scattered across the 4x2 grid.
         Left rack slots: L1@(col1,row1), L2@(col2,row2), L3@(col4,row1)
         Right rack slots: R1@(col1,row2), R2@(col3,row1), R3@(col4,row2)
         Columns: rel x ∈ {-0.06, -0.02, +0.02, +0.06}
         Rows:    rel y ∈ {-0.02 (front), +0.02 (back)} -->
    <!-- LEFT RACK TUBES -->
    <body name="tube_L1" pos="-0.510 0.130 0.8175">  <!-- col1 row1, orange -->
      <inertial pos="0 0 0.01" mass="0.03" diaginertia="3e-5 3e-5 5e-6"/>
      <geom name="tube_L1_body" class="tube_body" material="tube_body_mat" mass="0"/>
      <geom name="tube_L1_cap"  type="cylinder" size="0.0155 0.006"
            pos="0 0 0.0635" material="cap_orange_mat" mass="0"/>
      <joint type="free" name="tube_L1_joint"/>
    </body>
    <body name="tube_L2" pos="-0.470 0.170 0.8175">  <!-- col2 row2, blue -->
      <inertial pos="0 0 0.01" mass="0.03" diaginertia="3e-5 3e-5 5e-6"/>
      <geom name="tube_L2_body" class="tube_body" material="tube_body_mat" mass="0"/>
      <geom name="tube_L2_cap"  type="cylinder" size="0.0155 0.006"
            pos="0 0 0.0635" material="cap_blue_mat" mass="0"/>
      <joint type="free" name="tube_L2_joint"/>
    </body>
    <body name="tube_L3" pos="-0.390 0.130 0.8175">  <!-- col4 row1, orange -->
      <inertial pos="0 0 0.01" mass="0.03" diaginertia="3e-5 3e-5 5e-6"/>
      <geom name="tube_L3_body" class="tube_body" material="tube_body_mat" mass="0"/>
      <geom name="tube_L3_cap"  type="cylinder" size="0.0155 0.006"
            pos="0 0 0.0635" material="cap_orange_mat" mass="0"/>
      <joint type="free" name="tube_L3_joint"/>
    </body>
    <!-- RIGHT RACK TUBES -->
    <body name="tube_R1" pos="-0.510 0.320 0.8175">  <!-- col1 row2, blue (moved with right_tube_rack to back-left) -->
      <inertial pos="0 0 0.01" mass="0.03" diaginertia="3e-5 3e-5 5e-6"/>
      <geom name="tube_R1_body" class="tube_body" material="tube_body_mat" mass="0"/>
      <geom name="tube_R1_cap"  type="cylinder" size="0.0155 0.006"
            pos="0 0 0.0635" material="cap_blue_mat" mass="0"/>
      <joint type="free" name="tube_R1_joint"/>
    </body>
    <body name="tube_R2" pos="-0.430 0.280 0.8175">  <!-- col3 row1, orange (moved with right_tube_rack to back-left) -->
      <inertial pos="0 0 0.01" mass="0.03" diaginertia="3e-5 3e-5 5e-6"/>
      <geom name="tube_R2_body" class="tube_body" material="tube_body_mat" mass="0"/>
      <geom name="tube_R2_cap"  type="cylinder" size="0.0155 0.006"
            pos="0 0 0.0635" material="cap_orange_mat" mass="0"/>
      <joint type="free" name="tube_R2_joint"/>
    </body>
    <body name="tube_R3" pos="-0.390 0.320 0.8175">  <!-- col4 row2, blue (moved with right_tube_rack to back-left) -->
      <inertial pos="0 0 0.01" mass="0.03" diaginertia="3e-5 3e-5 5e-6"/>
      <geom name="tube_R3_body" class="tube_body" material="tube_body_mat" mass="0"/>
      <geom name="tube_R3_cap"  type="cylinder" size="0.0155 0.006"
            pos="0 0 0.0635" material="cap_blue_mat" mass="0"/>
      <joint type="free" name="tube_R3_joint"/>
    </body>

    <!-- =============================================================
         OPENTRONS OT-2 (static fixture, not actuated).

         Real outer dimensions: 630 W x 570 D x 660 H mm (from the
         official spec). In this sim the chassis is taller than real
         because the deck is held at bench height (z=0.755 m) for arm
         reachability -- imagine the OT-2 sitting on its own riser
         table. The enclosure above the deck is 500 mm tall instead
         of the real 230 mm, again to give the arm vertical clearance
         when it extends in through the front opening.

         Side walls + back wall + top are COLLIDING obstacles. Front
         face (-x, toward bench) is open. The arm must approach from
         the bench side; it cannot pass through any other face.

         Deck layout: 11 SBS slots in a 3 col x 4 row grid + TRASH at
         slot 12 (back-right corner). Numbering matches the Opentrons
         convention: 1-3 = front row (closest to bench), 4-6, 7-9,
         then 10-11 + TRASH at the back. Slot pitch is 132 mm (cols)
         x 89 mm (rows).

         Coordinate convention: OT-2 body at world (1.0, 0, 0); deck
         top surface at z=0.755; "front of deck" = -x in OT-2 local
         (= world x < 1.0). When the arm looks at the OT-2 from the
         bench (looking +x), its LEFT corresponds to OT-2 local +y.
    ============================================================= -->
    <body name="opentrons_ot2" pos="1.0 0.0 0.0">
      <!-- Chassis: solid box from z=0 to z=0.750. Visually represents
           the OT-2 base + riser table; functionally just an obstacle
           the arm can't pass through. Half-extents 0.315 x 0.285 x 0.375. -->
      <geom name="ot2_chassis" type="box" size="0.315 0.285 0.375"
            pos="0 0 0.375" material="ot2_chassis_mat"
            contype="1" conaffinity="1" mass="0"/>
      <!-- Deck plate: dark grey, 5mm thick, sits on the chassis top.
           Slightly inset (5mm) from chassis edge for a clean look. -->
      <geom name="ot2_deck" type="box" size="0.310 0.280 0.0025"
            pos="0 0 0.7525" material="ot2_deck_mat"
            contype="1" conaffinity="1" mass="0"/>

      <!-- Slot markers: 3 cols x 4 rows + TRASH (= 12 positions).
           Each slot has TWO visual cues:
           (1) a thin grey rectangle outlining the slot footprint
               (lets the user see the SBS slot boundary), AND
           (2) a colored circular tag in the back-right corner that
               identifies the slot NUMBER via its unique color
               (rainbow 1-11; dark grey for TRASH). Look at the
               opentrons_ot2 safety_notes for the colour <-> slot
               number mapping.
           All slot geoms are non-colliding so plates resting in
           slots don't catch on the marker geometry.
           Col offsets (local y): +0.132, 0, -0.132 (left, mid, right
           from the arm's POV looking +x toward the OT-2).
           Row offsets (local x): -0.133, -0.044, +0.044, +0.133
           (front, mid-front, mid-back, back). -->
      <!-- Slot outlines (grey rectangles indicating SBS footprints). -->
      <geom name="ot2_slot_1_outline"  type="box" size="0.064 0.043 0.0010"
            pos="-0.133 +0.132 0.755" material="ot2_slot_mat"
            contype="0" conaffinity="0" mass="0"/>
      <geom name="ot2_slot_2_outline"  type="box" size="0.064 0.043 0.0010"
            pos="-0.133  0.000 0.755" material="ot2_slot_mat"
            contype="0" conaffinity="0" mass="0"/>
      <geom name="ot2_slot_3_outline"  type="box" size="0.064 0.043 0.0010"
            pos="-0.133 -0.132 0.755" material="ot2_slot_mat"
            contype="0" conaffinity="0" mass="0"/>
      <geom name="ot2_slot_4_outline"  type="box" size="0.064 0.043 0.0010"
            pos="-0.044 +0.132 0.755" material="ot2_slot_mat"
            contype="0" conaffinity="0" mass="0"/>
      <geom name="ot2_slot_5_outline"  type="box" size="0.064 0.043 0.0010"
            pos="-0.044  0.000 0.755" material="ot2_slot_mat"
            contype="0" conaffinity="0" mass="0"/>
      <geom name="ot2_slot_6_outline"  type="box" size="0.064 0.043 0.0010"
            pos="-0.044 -0.132 0.755" material="ot2_slot_mat"
            contype="0" conaffinity="0" mass="0"/>
      <geom name="ot2_slot_7_outline"  type="box" size="0.064 0.043 0.0010"
            pos="+0.044 +0.132 0.755" material="ot2_slot_mat"
            contype="0" conaffinity="0" mass="0"/>
      <geom name="ot2_slot_8_outline"  type="box" size="0.064 0.043 0.0010"
            pos="+0.044  0.000 0.755" material="ot2_slot_mat"
            contype="0" conaffinity="0" mass="0"/>
      <geom name="ot2_slot_9_outline"  type="box" size="0.064 0.043 0.0010"
            pos="+0.044 -0.132 0.755" material="ot2_slot_mat"
            contype="0" conaffinity="0" mass="0"/>
      <geom name="ot2_slot_10_outline" type="box" size="0.064 0.043 0.0010"
            pos="+0.133 +0.132 0.755" material="ot2_slot_mat"
            contype="0" conaffinity="0" mass="0"/>
      <geom name="ot2_slot_11_outline" type="box" size="0.064 0.043 0.0010"
            pos="+0.133  0.000 0.755" material="ot2_slot_mat"
            contype="0" conaffinity="0" mass="0"/>
      <geom name="ot2_slot_trash_outline" type="box" size="0.064 0.043 0.0010"
            pos="+0.133 -0.132 0.755" material="ot2_frame_mat"
            contype="0" conaffinity="0" mass="0"/>
      <!-- Colored slot-number identifier tags. Each is a small
           cylinder in the back-right corner of its slot (back =
           +x in OT-2 local; right = -y in OT-2 local).
           Tag offset from slot centre: (+0.055, -0.034). Tag size:
           radius 0.010m, height 0.004m. Placed at z=0.758 so they
           sit just above the deck outline. -->
      <geom name="ot2_slot_1_tag"  type="cylinder" size="0.010 0.004"
            pos="-0.078 +0.098 0.760" material="slot_1_mat"
            contype="0" conaffinity="0" mass="0"/>
      <geom name="ot2_slot_2_tag"  type="cylinder" size="0.010 0.004"
            pos="-0.078 -0.034 0.760" material="slot_2_mat"
            contype="0" conaffinity="0" mass="0"/>
      <geom name="ot2_slot_3_tag"  type="cylinder" size="0.010 0.004"
            pos="-0.078 -0.166 0.760" material="slot_3_mat"
            contype="0" conaffinity="0" mass="0"/>
      <geom name="ot2_slot_4_tag"  type="cylinder" size="0.010 0.004"
            pos="+0.011 +0.098 0.760" material="slot_4_mat"
            contype="0" conaffinity="0" mass="0"/>
      <geom name="ot2_slot_5_tag"  type="cylinder" size="0.010 0.004"
            pos="+0.011 -0.034 0.760" material="slot_5_mat"
            contype="0" conaffinity="0" mass="0"/>
      <geom name="ot2_slot_6_tag"  type="cylinder" size="0.010 0.004"
            pos="+0.011 -0.166 0.760" material="slot_6_mat"
            contype="0" conaffinity="0" mass="0"/>
      <geom name="ot2_slot_7_tag"  type="cylinder" size="0.010 0.004"
            pos="+0.099 +0.098 0.760" material="slot_7_mat"
            contype="0" conaffinity="0" mass="0"/>
      <geom name="ot2_slot_8_tag"  type="cylinder" size="0.010 0.004"
            pos="+0.099 -0.034 0.760" material="slot_8_mat"
            contype="0" conaffinity="0" mass="0"/>
      <geom name="ot2_slot_9_tag"  type="cylinder" size="0.010 0.004"
            pos="+0.099 -0.166 0.760" material="slot_9_mat"
            contype="0" conaffinity="0" mass="0"/>
      <geom name="ot2_slot_10_tag" type="cylinder" size="0.010 0.004"
            pos="+0.188 +0.098 0.760" material="slot_10_mat"
            contype="0" conaffinity="0" mass="0"/>
      <geom name="ot2_slot_11_tag" type="cylinder" size="0.010 0.004"
            pos="+0.188 -0.034 0.760" material="slot_11_mat"
            contype="0" conaffinity="0" mass="0"/>
      <geom name="ot2_slot_trash_tag" type="cylinder" size="0.010 0.004"
            pos="+0.188 -0.166 0.760" material="slot_trash_mat"
            contype="0" conaffinity="0" mass="0"/>

      <!-- Enclosure walls: COLLIDING. Side walls + back wall + top.
           Front face (-x) intentionally absent -- that's the access
           opening for the arm. Wall extents are 0.250 vertical
           half-extent (500 mm enclosure height), thin (5mm) in the
           normal direction. -->
      <geom name="ot2_back_wall"  class="ot2_wall"
            size="0.005 0.285 0.250" pos="+0.315 0.000 1.005"/>
      <geom name="ot2_left_wall"  class="ot2_wall"
            size="0.315 0.005 0.250" pos="0.000 +0.285 1.005"/>
      <geom name="ot2_right_wall" class="ot2_wall"
            size="0.315 0.005 0.250" pos="0.000 -0.285 1.005"/>
      <geom name="ot2_top"        class="ot2_wall"
            size="0.315 0.285 0.005" pos="0.000 0.000 1.260"/>

      <!-- Front frame trim (visual only, non-colliding): thin top
           edge + corner posts at the open face so it reads as an
           "open-front box" rather than "missing wall". -->
      <geom name="ot2_front_top" type="box" size="0.005 0.285 0.025"
            pos="-0.315 0.000 1.230" material="ot2_frame_mat"
            contype="0" conaffinity="0" mass="0"/>
      <geom name="ot2_front_post_l" type="box" size="0.005 0.005 0.250"
            pos="-0.315 +0.285 1.005" material="ot2_frame_mat"
            contype="0" conaffinity="0" mass="0"/>
      <geom name="ot2_front_post_r" type="box" size="0.005 0.005 0.250"
            pos="-0.315 -0.285 1.005" material="ot2_frame_mat"
            contype="0" conaffinity="0" mass="0"/>
      <!-- Logo strip (blue band on the front top edge) -->
      <geom name="ot2_logo_strip" type="box" size="0.005 0.060 0.012"
            pos="-0.320 0.000 1.210" material="ot2_logo_mat"
            contype="0" conaffinity="0" mass="0"/>
    </body>

    <!-- 96-well plate A: sits in OT-2 slot 1 (front-left) at session
         start. World (0.867, +0.132, 0.7625) = OT-2 origin + slot 1
         offset + plate half-thickness. -->
    <body name="well_plate_A" pos="0.867 +0.132 0.7625">
      <inertial pos="0 0 0" mass="0.10" diaginertia="2e-4 2e-4 3e-4"/>
      <geom name="well_plate_A_body" class="well_plate_body"
            material="well_plate_mat"/>
      <geom name="well_plate_A_top" type="box" size="0.038 0.058 0.0015"
            pos="0 0 0.0085" material="well_plate_top_mat" mass="0"
            contype="0" conaffinity="0"/>
      <joint type="free" name="well_plate_A_joint"/>
    </body>

    <!-- 96-well plate B: sits on the bench front-right, between the
         PCR thermocycler (at +0.20, -0.20) and the OT-2 (at +1.00, 0).
         Free body so the arm can pick it up and place it elsewhere
         (e.g. into the PCR, onto the heater_shaker, or onto an OT-2
         deck slot). -->
    <body name="well_plate_B" pos="+0.550 -0.200 0.7625">
      <inertial pos="0 0 0" mass="0.10" diaginertia="2e-4 2e-4 3e-4"/>
      <geom name="well_plate_B_body" class="well_plate_body"
            material="well_plate_mat"/>
      <geom name="well_plate_B_top" type="box" size="0.038 0.058 0.0015"
            pos="0 0 0.0085" material="well_plate_top_mat" mass="0"
            contype="0" conaffinity="0"/>
      <joint type="free" name="well_plate_B_joint"/>
    </body>

    <!-- Tip box: standard SBS tip rack (127 x 85 x 80 mm). Sits in
         OT-2 slot 10 (back-left). NOTE: slot 10 is at world x=1.133,
         which is at the edge of the arm's reach through the OT-2's
         front opening when colliding side walls are in place. The
         arm may not be able to pick this tip box up from rail=700;
         that's intentional -- the user explicitly placed it there
         to test reachability + as a visual fixture. -->
    <body name="tip_box" pos="1.133 +0.132 0.795">
      <inertial pos="0 0 0" mass="0.20" diaginertia="3e-4 3e-4 4e-4"/>
      <geom name="tip_box_body" class="tip_box_body"
            material="tip_box_mat"/>
      <!-- Cosmetic top to read as "tip rack grid". -->
      <geom name="tip_box_top" type="box" size="0.038 0.058 0.0015"
            pos="0 0 0.041" material="tip_box_top_mat" mass="0"
            contype="0" conaffinity="0"/>
      <joint type="free" name="tip_box_joint"/>
    </body>

    <!-- Opentrons Heater-Shaker module (152 W x 90 D x 82 H mm).
         Sits on the bench, front-left. Heavy (2 kg) so it stays put
         unless deliberately pushed. The flat top is a plate-sized
         surface the arm can place a 96-well plate onto. -->
    <body name="heater_shaker" pos="-0.300 -0.250 0.791">
      <inertial pos="0 0 0" mass="2.0" diaginertia="3e-3 3e-3 5e-3"/>
      <geom name="heater_shaker_body" class="heater_shaker_body"
            material="heater_shaker_mat"/>
      <!-- Flat shaker platform on top (slightly recessed). -->
      <geom name="heater_shaker_platform" type="box"
            size="0.070 0.043 0.002" pos="0 0 0.043"
            material="heater_shaker_top_mat" mass="0"
            contype="1" conaffinity="1"/>
      <!-- Blue accent strip on the front face (signature Opentrons look). -->
      <geom name="heater_shaker_logo" type="box"
            size="0.030 0.001 0.008" pos="0 -0.046 0.030"
            material="heater_shaker_accent_mat" mass="0"
            contype="0" conaffinity="0"/>
      <joint type="free" name="heater_shaker_joint"/>
    </body>

    <!-- =============================================================
         VORTEX-GENIE 2 (classic benchtop vortex mixer).
         Outer dimensions 165 W x 122 D x 165 H mm (per spec).

         Layout: chassis (grey rectangular base) -> short black neck
         -> flat black rubber platform on top. When an object is
         placed on the platform, _vortex_tick() (in SimXArmAPI) drives
         two slide joints in a 4 mm-radius circle so the platform
         orbits the object visibly. High friction on the platform
         drags the object along.

         Position: world (-0.20, +0.25, 0.75) -- the bench-top spot
         where the now-deleted red_cube + red_bin used to live.
         Static fixture (body has no free joint).
    ============================================================= -->
    <body name="vortex_genie" pos="-0.20 0.25 0.75">
      <!-- Chassis: 165 W x 122 D x 130 H mm. Centred at z=0.065 so
           the chassis bottom sits on the bench (z=0) and the top is
           at z=0.130. -->
      <geom name="vortex_chassis" type="box"
            size="0.0825 0.061 0.065" pos="0 0 0.065"
            material="vortex_chassis_mat"
            contype="1" conaffinity="1" mass="0"/>
      <!-- Neck: short black collar between chassis and platform. -->
      <geom name="vortex_neck" type="box"
            size="0.040 0.040 0.010" pos="0 0 0.140"
            material="vortex_neck_mat"
            contype="1" conaffinity="1" mass="0"/>
      <!-- Speed dial on the front face. -->
      <geom name="vortex_dial" type="cylinder"
            size="0.018 0.005" pos="0 -0.061 0.045"
            euler="1.5708 0 0"
            material="vortex_dial_mat"
            contype="0" conaffinity="0" mass="0"/>
      <!-- Brand strip on the front face (red "Genie 2" colour). -->
      <geom name="vortex_logo" type="box"
            size="0.035 0.001 0.008" pos="0 -0.062 0.095"
            material="vortex_logo_mat"
            contype="0" conaffinity="0" mass="0"/>

      <!-- Power-indicator LEDs: one yellow disc on each of the chassis's
           four side faces. Now 2x larger (radius 9mm, length 8mm) than
           the first pass so they're visible at typical camera distance.
           Positioned so each LED's inner face is flush with its chassis
           face and 8mm proud of it. SimXArmAPI._vortex_tick switches
           their rgba on/off when the vortex starts/stops shaking;
           default rgba below = the OFF state (dim yellow). -->
      <geom name="vortex_led_front" type="cylinder"
            size="0.009 0.004" pos="0 -0.0865 0.115"
            euler="1.5708 0 0"
            rgba="0.18 0.15 0.02 1"
            contype="0" conaffinity="0" mass="0"/>
      <geom name="vortex_led_back" type="cylinder"
            size="0.009 0.004" pos="0 +0.0865 0.115"
            euler="1.5708 0 0"
            rgba="0.18 0.15 0.02 1"
            contype="0" conaffinity="0" mass="0"/>
      <geom name="vortex_led_left" type="cylinder"
            size="0.009 0.004" pos="-0.0865 0 0.115"
            euler="0 1.5708 0"
            rgba="0.18 0.15 0.02 1"
            contype="0" conaffinity="0" mass="0"/>
      <geom name="vortex_led_right" type="cylinder"
            size="0.009 0.004" pos="+0.0865 0 0.115"
            euler="0 1.5708 0"
            rgba="0.18 0.15 0.02 1"
            contype="0" conaffinity="0" mass="0"/>

      <!-- Orbital platform: child body with two slide joints so it
           can be driven in a 4 mm-radius circle around its rest
           position. Joint range is +/-0.006 m to give the orbital
           radius (4 mm) a 2 mm buffer. The cylinder geom is at
           local z=0 inside this sub-body, which itself is at chassis
           local z=0.155 -- so the platform top surface is at world
           z = 0.75 + 0.155 + 0.005 = 0.910. -->
      <body name="vortex_platform" pos="0 0 0.155">
        <inertial pos="0 0 0" mass="0.02"
                  diaginertia="2e-5 2e-5 3e-5"/>
        <joint name="vortex_orbit_x" type="slide" axis="1 0 0"
               range="-0.006 0.006" limited="true"
               damping="0.05" stiffness="0"/>
        <joint name="vortex_orbit_y" type="slide" axis="0 1 0"
               range="-0.006 0.006" limited="true"
               damping="0.05" stiffness="0"/>
        <geom name="vortex_platform_top" class="vortex_platform_geom"
              material="vortex_platform_mat"
              contype="1" conaffinity="1"/>
      </body>
    </body>

    <!-- =============================================================
         OPENTRONS THERMOCYCLER MODULE (PCR machine).
         Approx outer dimensions 170 x 350 x 130 mm (compressed from
         the real ~172 x 396 to fit the bench).

         Body is ROTATED 90deg CCW around world +z so the long axis
         is along world x. This places the hinged-lid edge on the -x
         face (away from the OT-2 at world +x) and moves the
         chassis's long axis out of the arm-base sweep zone.
         World footprint after rotation:
           x in (0.025, 0.375)
           y in (-0.385, -0.215)
         Arm base sweeps y in (-0.11, +0.01) along the rail, so
         there's >100mm of y clearance even at the closest rail
         position.

         Layout: open-top chassis (floor + 4 walls, collidable) + a
         dark heated-block inside where a 96-well plate sits +
         hinged lid that rotates 0 to pi/2 around the local +x axis
         (after rotation this is the world +y axis at the back-top
         edge of the chassis). Closed lid sits flat over the chassis
         top; open lid stands vertical at the -x face (world x ~0.025)
         pointing UP -- away from the OT-2.

         Two LED indicators on the (now world-front and world-back)
         faces show state:
           - GREEN = a plate is detected inside the cavity
           - RED   = no plate inside AND lid is closed
           - dim grey = no plate inside AND lid is open
         SimXArmAPI._pcr_tick updates the LED rgba each step.

         Lid actuator: act_pcr_lid (see <actuator>). ctrl=0 -> closed.
         ctrl=pi/2 -> open (lid stands vertical at the -x face).
    ============================================================= -->
    <body name="pcr_module" pos="0.20 -0.30 0.75" euler="0 0 1.5708">
      <!-- Chassis: open-top box. Floor + 4 walls. Half-extents
           ~(0.085, 0.175, 0.005-0.045) on each piece. -->
      <geom name="pcr_chassis_floor" type="box"
            size="0.085 0.175 0.005" pos="0 0 0.005"
            material="pcr_chassis_mat"
            contype="1" conaffinity="1" mass="0"/>
      <geom name="pcr_chassis_back" type="box"
            size="0.085 0.005 0.045" pos="0 +0.170 0.055"
            material="pcr_chassis_mat"
            contype="1" conaffinity="1" mass="0"/>
      <geom name="pcr_chassis_front" type="box"
            size="0.085 0.005 0.045" pos="0 -0.170 0.055"
            material="pcr_chassis_mat"
            contype="1" conaffinity="1" mass="0"/>
      <geom name="pcr_chassis_left" type="box"
            size="0.005 0.175 0.045" pos="-0.080 0 0.055"
            material="pcr_chassis_mat"
            contype="1" conaffinity="1" mass="0"/>
      <geom name="pcr_chassis_right" type="box"
            size="0.005 0.175 0.045" pos="+0.080 0 0.055"
            material="pcr_chassis_mat"
            contype="1" conaffinity="1" mass="0"/>
      <!-- Heated block: where the 96-well plate sits. Slightly
           smaller than SBS footprint so the plate can drop into
           the recess without snagging. -->
      <geom name="pcr_block" type="box"
            size="0.060 0.043 0.005" pos="0 0 0.015"
            material="pcr_block_mat"
            contype="1" conaffinity="1" mass="0"/>
      <!-- Display panel on the front face (visual only). -->
      <geom name="pcr_display" type="box"
            size="0.045 0.001 0.015" pos="0 -0.176 0.030"
            material="pcr_display_mat"
            contype="0" conaffinity="0" mass="0"/>
      <!-- Opentrons logo strip on the front face (visual only). -->
      <geom name="pcr_logo" type="box"
            size="0.020 0.001 0.005" pos="0 -0.176 0.080"
            material="pcr_logo_mat"
            contype="0" conaffinity="0" mass="0"/>
      <!-- LED indicators: one on each side face (left/right). Default
           rgba = dim grey (off). SimXArmAPI._pcr_tick writes
           red/green based on state. -->
      <geom name="pcr_led_left" type="cylinder"
            size="0.009 0.004" pos="-0.089 0 0.070"
            euler="0 1.5708 0"
            rgba="0.15 0.15 0.15 1"
            contype="0" conaffinity="0" mass="0"/>
      <geom name="pcr_led_right" type="cylinder"
            size="0.009 0.004" pos="+0.089 0 0.070"
            euler="0 1.5708 0"
            rgba="0.15 0.15 0.15 1"
            contype="0" conaffinity="0" mass="0"/>

      <!-- Lid: child body hinged at the back-top edge of the chassis.
           Hinge axis = world x; range [0, pi/2]. Lid extends FORWARD
           (in -y direction) from the hinge when closed. -->
      <body name="pcr_lid" pos="0 0.170 0.110">
        <inertial pos="0 -0.087 0" mass="0.3"
                  diaginertia="3e-3 3e-3 5e-3"/>
        <!-- axis="-1 0 0" so a positive joint angle rotates the lid
             panel UPWARD (right-hand rule around -x). With axis="1 0 0"
             the same +pi/2 ctrl would rotate the panel DOWNWARD
             through the chassis floor. -->
        <joint name="pcr_lid_hinge" type="hinge" axis="-1 0 0"
               range="0 1.5708" limited="true"
               damping="2.0"/>
        <!-- Lid panel: 170 W x 175 D x 15 H mm. -->
        <geom name="pcr_lid_top" type="box"
              size="0.085 0.0875 0.0075" pos="0 -0.0875 0"
              material="pcr_lid_mat"
              contype="1" conaffinity="1"/>
        <!-- Lid handle / front lip (cosmetic). -->
        <geom name="pcr_lid_handle" type="box"
              size="0.030 0.005 0.012" pos="0 -0.170 -0.012"
              material="pcr_logo_mat"
              contype="0" conaffinity="0" mass="0"/>
      </body>
    </body>

    <!-- =============================================================
         LED STRIPS (2 x 700mm) flanking the rail.
         Each strip = a dark PCB base + 15 individually-coloured LED
         chips spaced 50mm apart. The chip rgbas are updated at
         runtime by SimXArmAPI._led_tick to show rainbow direction-
         flow when the rail is moving. The flow speed scales with
         the active --speed-tier.

         Strip A sits in front of the rail (y=-0.085). Strip B sits
         behind the rail (y=-0.015). Both are at z=0.766 -- just
         above the rail body's top, so they stand visibly proud of
         the rail without colliding with the carriage.

         All LED chip + PCB geoms are non-colliding (contype=0).
    ============================================================= -->
    <body name="led_strip_A" pos="0 -0.085 0.766">
      <geom name="led_strip_A_pcb" type="box"
            size="0.350 0.0150 0.0030" pos="0 0 0"
            material="led_pcb_mat"
            contype="0" conaffinity="0" mass="0"/>
      <geom name="led_A_01" type="box" size="0.024 0.010 0.006" pos="-0.325 0 0.0090" rgba="0.05 0.05 0.05 1" contype="0" conaffinity="0" mass="0"/>
      <geom name="led_A_02" type="box" size="0.024 0.010 0.006" pos="-0.275 0 0.0090" rgba="0.05 0.05 0.05 1" contype="0" conaffinity="0" mass="0"/>
      <geom name="led_A_03" type="box" size="0.024 0.010 0.006" pos="-0.225 0 0.0090" rgba="0.05 0.05 0.05 1" contype="0" conaffinity="0" mass="0"/>
      <geom name="led_A_04" type="box" size="0.024 0.010 0.006" pos="-0.175 0 0.0090" rgba="0.05 0.05 0.05 1" contype="0" conaffinity="0" mass="0"/>
      <geom name="led_A_05" type="box" size="0.024 0.010 0.006" pos="-0.125 0 0.0090" rgba="0.05 0.05 0.05 1" contype="0" conaffinity="0" mass="0"/>
      <geom name="led_A_06" type="box" size="0.024 0.010 0.006" pos="-0.075 0 0.0090" rgba="0.05 0.05 0.05 1" contype="0" conaffinity="0" mass="0"/>
      <geom name="led_A_07" type="box" size="0.024 0.010 0.006" pos="-0.025 0 0.0090" rgba="0.05 0.05 0.05 1" contype="0" conaffinity="0" mass="0"/>
      <geom name="led_A_08" type="box" size="0.024 0.010 0.006" pos=" 0.025 0 0.0090" rgba="0.05 0.05 0.05 1" contype="0" conaffinity="0" mass="0"/>
      <geom name="led_A_09" type="box" size="0.024 0.010 0.006" pos=" 0.075 0 0.0090" rgba="0.05 0.05 0.05 1" contype="0" conaffinity="0" mass="0"/>
      <geom name="led_A_10" type="box" size="0.024 0.010 0.006" pos=" 0.125 0 0.0090" rgba="0.05 0.05 0.05 1" contype="0" conaffinity="0" mass="0"/>
      <geom name="led_A_11" type="box" size="0.024 0.010 0.006" pos=" 0.175 0 0.0090" rgba="0.05 0.05 0.05 1" contype="0" conaffinity="0" mass="0"/>
      <geom name="led_A_12" type="box" size="0.024 0.010 0.006" pos=" 0.225 0 0.0090" rgba="0.05 0.05 0.05 1" contype="0" conaffinity="0" mass="0"/>
      <geom name="led_A_13" type="box" size="0.024 0.010 0.006" pos=" 0.275 0 0.0090" rgba="0.05 0.05 0.05 1" contype="0" conaffinity="0" mass="0"/>
      <geom name="led_A_14" type="box" size="0.024 0.010 0.006" pos=" 0.325 0 0.0090" rgba="0.05 0.05 0.05 1" contype="0" conaffinity="0" mass="0"/>
    </body>

    <body name="led_strip_B" pos="0 -0.015 0.766">
      <geom name="led_strip_B_pcb" type="box"
            size="0.350 0.0150 0.0030" pos="0 0 0"
            material="led_pcb_mat"
            contype="0" conaffinity="0" mass="0"/>
      <geom name="led_B_01" type="box" size="0.024 0.010 0.006" pos="-0.325 0 0.0090" rgba="0.05 0.05 0.05 1" contype="0" conaffinity="0" mass="0"/>
      <geom name="led_B_02" type="box" size="0.024 0.010 0.006" pos="-0.275 0 0.0090" rgba="0.05 0.05 0.05 1" contype="0" conaffinity="0" mass="0"/>
      <geom name="led_B_03" type="box" size="0.024 0.010 0.006" pos="-0.225 0 0.0090" rgba="0.05 0.05 0.05 1" contype="0" conaffinity="0" mass="0"/>
      <geom name="led_B_04" type="box" size="0.024 0.010 0.006" pos="-0.175 0 0.0090" rgba="0.05 0.05 0.05 1" contype="0" conaffinity="0" mass="0"/>
      <geom name="led_B_05" type="box" size="0.024 0.010 0.006" pos="-0.125 0 0.0090" rgba="0.05 0.05 0.05 1" contype="0" conaffinity="0" mass="0"/>
      <geom name="led_B_06" type="box" size="0.024 0.010 0.006" pos="-0.075 0 0.0090" rgba="0.05 0.05 0.05 1" contype="0" conaffinity="0" mass="0"/>
      <geom name="led_B_07" type="box" size="0.024 0.010 0.006" pos="-0.025 0 0.0090" rgba="0.05 0.05 0.05 1" contype="0" conaffinity="0" mass="0"/>
      <geom name="led_B_08" type="box" size="0.024 0.010 0.006" pos=" 0.025 0 0.0090" rgba="0.05 0.05 0.05 1" contype="0" conaffinity="0" mass="0"/>
      <geom name="led_B_09" type="box" size="0.024 0.010 0.006" pos=" 0.075 0 0.0090" rgba="0.05 0.05 0.05 1" contype="0" conaffinity="0" mass="0"/>
      <geom name="led_B_10" type="box" size="0.024 0.010 0.006" pos=" 0.125 0 0.0090" rgba="0.05 0.05 0.05 1" contype="0" conaffinity="0" mass="0"/>
      <geom name="led_B_11" type="box" size="0.024 0.010 0.006" pos=" 0.175 0 0.0090" rgba="0.05 0.05 0.05 1" contype="0" conaffinity="0" mass="0"/>
      <geom name="led_B_12" type="box" size="0.024 0.010 0.006" pos=" 0.225 0 0.0090" rgba="0.05 0.05 0.05 1" contype="0" conaffinity="0" mass="0"/>
      <geom name="led_B_13" type="box" size="0.024 0.010 0.006" pos=" 0.275 0 0.0090" rgba="0.05 0.05 0.05 1" contype="0" conaffinity="0" mass="0"/>
      <geom name="led_B_14" type="box" size="0.024 0.010 0.006" pos=" 0.325 0 0.0090" rgba="0.05 0.05 0.05 1" contype="0" conaffinity="0" mass="0"/>
    </body>

  </worldbody>

  <contact>
    <exclude body1="rail_carriage" body2="xarm_base"/>
    <exclude body1="rail_carriage" body2="link1"/>
    <exclude body1="xarm_base"     body2="link1"/>
    <exclude body1="link1"         body2="link2"/>
    <exclude body1="link2"         body2="link3"/>
    <exclude body1="link3"         body2="link4"/>
    <exclude body1="link4"         body2="link5"/>
    <exclude body1="link5"         body2="link6"/>
    <exclude body1="link6"         body2="gripper"/>
  </contact>

  <!-- ============================================================
       MAGNETIC-GRIPPER WELDS (runtime-toggled).
       Inactive by default. SimXArmAPI activates the weld for the
       cube nearest the gripper on gripper_close(), deactivates all
       on gripper_open(). Locks the cube-gripper relative pose so
       the cube is "carried" while the weld is active.
  ============================================================ -->
  <equality>
    <weld name="grip_green_cube" body1="gripper" body2="green_cube" active="false"/>
    <weld name="grip_blue_cube"  body1="gripper" body2="blue_cube"  active="false"/>
    <weld name="grip_tube_L1"    body1="gripper" body2="tube_L1"    active="false"/>
    <weld name="grip_tube_L2"    body1="gripper" body2="tube_L2"    active="false"/>
    <weld name="grip_tube_L3"    body1="gripper" body2="tube_L3"    active="false"/>
    <weld name="grip_tube_R1"    body1="gripper" body2="tube_R1"    active="false"/>
    <weld name="grip_tube_R2"    body1="gripper" body2="tube_R2"    active="false"/>
    <weld name="grip_tube_R3"    body1="gripper" body2="tube_R3"    active="false"/>
    <weld name="grip_green_bin"  body1="gripper" body2="green_bin"  active="false"/>
    <weld name="grip_blue_bin"   body1="gripper" body2="blue_bin"   active="false"/>
    <weld name="grip_left_rack"  body1="gripper" body2="left_tube_rack"  active="false"/>
    <weld name="grip_right_rack" body1="gripper" body2="right_tube_rack" active="false"/>
    <weld name="grip_well_plate_A" body1="gripper" body2="well_plate_A" active="false"/>
    <weld name="grip_well_plate_B" body1="gripper" body2="well_plate_B" active="false"/>
    <weld name="grip_tip_box"      body1="gripper" body2="tip_box"      active="false"/>
    <weld name="grip_heater_shaker" body1="gripper" body2="heater_shaker" active="false"/>
  </equality>

  <actuator>
    <position name="act_rail" joint="rail"   kp="2000" kv="200"/>
    <position name="act1"     joint="joint1" kp="500"  kv="50"/>
    <position name="act2"     joint="joint2" kp="500"  kv="50"/>
    <position name="act3"     joint="joint3" kp="400"  kv="40"/>
    <position name="act4"     joint="joint4" kp="300"  kv="30"/>
    <position name="act5"     joint="joint5" kp="200"  kv="20"/>
    <position name="act6"     joint="joint6" kp="150"  kv="15"/>
    <!-- Cosmetic finger actuators. ctrl in [0, 0.015] m: 0 = open, 0.015 =
         closed. SimXArmAPI drives both to the same value from gripper_close/
         gripper_open, so they always move in sync. -->
    <position name="act_finger_l" joint="finger_left_joint"
              kp="200" kv="20" ctrlrange="0 0.015"/>
    <position name="act_finger_r" joint="finger_right_joint"
              kp="200" kv="20" ctrlrange="0 0.015"/>
    <!-- Vortex-Genie orbital platform actuators. SimXArmAPI's
         _vortex_tick drives ctrl to (R*cos(wt), R*sin(wt)) when an
         object is detected on the platform; both back to 0 otherwise.
         Joint range is +/-6mm; orbit radius commanded is 4mm. -->
    <position name="act_vortex_x" joint="vortex_orbit_x"
              kp="1000" kv="8" ctrlrange="-0.006 0.006"/>
    <position name="act_vortex_y" joint="vortex_orbit_y"
              kp="1000" kv="8" ctrlrange="-0.006 0.006"/>
    <!-- PCR thermocycler lid hinge. ctrl=0 -> closed; ctrl=pi/2 ->
         fully open (lid stands vertical at the back of the chassis).
         SimXArmAPI.set_pcr_lid drives this actuator. -->
    <position name="act_pcr_lid" joint="pcr_lid_hinge"
              kp="80" kv="10" ctrlrange="0 1.5708"/>
  </actuator>

</mujoco>
